Workbook

Sheet Industry Info
B3: Hotel Industry
B4: > Industry is very much dependent on Domestic and International Tourism. > Very much volatile as per economy conditions - Industry booms during econmic boom and during Slowdown/recession industry suffers. > With average 6-9% GDP growth for last 5yrs and continued to grow in same line for another few year resulted in increased disposable income and higher demand for better, improved services in hospitality sector. Especially demand for luxury and affordable hotels is increasing steadily. >

Sheet BalanceSheet
B5: Description | C5: Sch | D5: 31-Mar, 2009 | G5: 31-Mar, 2008 | J5: 31-Mar, 2007 | M5: 31-Mar, 2006
B7: Source of Funds
B9: Shareholder funds
B10: Capital | D10: 272339650 | E10: =D10/D22 -> 0.1055611 | G10: 272339650 | H10: =G10/G22 -> 0.13816432 | J10: 272339650 | K10: =J10/J22 -> 0.14340545 | M10: 272339650 | N10: =M10/M22 -> 0.15113343
B11: Reserves and Surplus | D11: 1633718747 | E11: =D11/D22 -> 0.63324291 | G11: 1488606379 | H11: =G11/G22 -> 0.75520508 | J11: 1372980838 | K11: =J11/J22 -> 0.72296833 | M11: 1225089917 | N11: =M11/M22 -> 0.67985708
B12: Employee Stock options outstanding Account | D12: 985360 | E12: =D12/D22 -> 0.00038193369 | G12: 598896 | H12: =G12/G22 -> 0.00030383405 | J12: 0 | K12: =J12/J22 -> 0 | M12: 0 | N12: =M12/M22 -> 0
D13: =SUM(D10:D12) -> 1907043757 | G13: =SUM(G10:G12) -> 1761544925 | J13: =SUM(J10:J12) -> 1645320488 | M13: =SUM(M10:M12) -> 1497429567
B15: Loan Funds
B16: Secured Loans | D16: 618880491 | E16: =D16/D22 -> 0.2398832 | G16: 169583730 | H16: =G16/G22 -> 0.086033821 | J16: 220768018 | K16: =J16/J22 -> 0.11624946 | M16: 269351992 | N16: =M16/M22 -> 0.14947544
B17: Un-Secured Loans | D17: - | G17: - | J17: - | M17: -
D18: =SUM(D16:D17) -> 618880491 | G18: =SUM(G16:G17) -> 169583730 | J18: =SUM(J16:J17) -> 220768018 | M18: =SUM(M16:M17) -> 269351992
B20: Deferred Tax Liability | D20: 54000000 | E20: =D20/D22 -> 0.020930847 | G20: 40000000 | H20: =G20/G22 -> 0.020292942 | J20: 33000000 | K20: =J20/J22 -> 0.017376757 | M20: 35200000 | N20: =M20/M22 -> 0.019534051
B22: Total | D22: =D13+D18+D20 -> 2579924248 | E22: =SUM(E10:E21) -> 1 | G22: =G13+G18+G20 -> 1971128655 | H22: =SUM(H10:H21) -> 1 | J22: =J13+J18+J20 -> 1899088506 | K22: =SUM(K10:K21) -> 1 | M22: =M13+M18+M20 -> 1801981559 | N22: =SUM(N10:N21) -> 1
B24: Application of Funds
B26: Fixed Assets
B27: Gross Block | D27: 773776937 | E27: =D27/D51 -> 0.29995723 | G27: 681598763 | H27: =G27/G51 -> 0.34579111 | J27: 530648269 | K27: =J27/J51 -> 0.27942261 | M27: 434823424 | N27: =M27/M51 -> 0.24130293
B28: Less: Accumulated Depreciation/Amortization | D28: -198421855 | E28: =D28/D51 -> -0.076918898 | G28: -141955149 | H28: =G28/G51 -> -0.072017191 | J28: -109807488 | K28: =J28/J51 -> -0.057821153 | M28: -76473941 | N28: =M28/M51 -> -0.042438803
B29: Net Block | D29: =SUM(D27:D28) -> 575355082 | G29: =SUM(G27:G28) -> 539643614 | J29: =SUM(J27:J28) -> 420840781 | M29: =SUM(M27:M28) -> 358349483
B30: Capital - WIP (including capital Advance) | D30: 437657565 | E30: =D30/D51 -> 0.16965942 | G30: 116615620 | H30: =G30/G51 -> 0.059161851 | J30: 3370096 | K30: =J30/J51 -> 0.0017745861 | M30: 8403598 | N30: =M30/M51 -> 0.0046635316
D31: =SUM(D29:D30) -> 1013012647 | G31: =SUM(G29:G30) -> 656259234 | J31: =SUM(J29:J30) -> 424210877 | M31: =SUM(M29:M30) -> 366753081
B33: Investments | D33: 864702456 | E33: =D33/D51 -> 0.33520481 | G33: 618448512 | H33: =G33/G51 -> 0.3137535 | J33: 107749000 | K33: =J33/J51 -> 0.056737219 | M33: 62049000 | N33: =M33/M51 -> 0.03443376
B35: Current Assets, Loans and Advances
B36: Inventories | D36: 10733932 | E36: =D36/D51 -> 0.0041610448 | G36: 11654212 | H36: =G36/G51 -> 0.0059124563 | J36: 5039481 | K36: =J36/J51 -> 0.0026536315 | M36: 5388165 | N36: =M36/M51 -> 0.0029901333
B37: Sundry Debtors | D37: 60644060 | E37: =D37/D51 -> 0.023508873 | G37: 33220336 | H37: =G37/G51 -> 0.016853459 | J37: 44259490 | K37: =J37/J51 -> 0.023305649 | M37: 34222268 | N37: =M37/M51 -> 0.018991464
B38: Unbilled Revenue | D38: 7620321 | E38: =D38/D51 -> 0.002954043 | G38: 6661365 | H38: =G38/G51 -> 0.0033794674 | J38: 2496437 | K38: =J38/J51 -> 0.0013145448 | M38: 6282627 | N38: =M38/M51 -> 0.0034865102
B39: Cash and Bank Balance | D39: 227159339 | E39: =D39/D51 -> 0.08805908 | G39: 467930601 | H39: =G39/G51 -> 0.23739222 | J39: 1210272005 | K39: =J39/J51 -> 0.637291 | M39: 1401533640 | N39: =M39/M51 -> 0.77777358
B40: Loans and Advances | D40: 571510827 | E40: =D40/D51 -> 0.22154809 | G40: 479675929 | H40: =G40/G51 -> 0.2433509 | J40: 385250333 | K40: =J40/J51 -> 0.20286065 | M40: 167124658 | N40: =M40/M51 -> 0.092744932
D41: =SUM(D36:D40) -> 877668479 | G41: =SUM(G36:G40) -> 999142443 | J41: =SUM(J36:J40) -> 1647317746 | M41: =SUM(M36:M40) -> 1614551358
B43: Less: Current Liability and Provisions
B44: Liability | D44: 115249720 | E44: =-D44/D51 -> -0.044676941 | G44: 104660074 | H44: =-G44/G51 -> -0.053096521 | J44: 83897767 | K44: =-J44/J51 -> -0.044177913 | M44: 81825107 | N44: =-M44/M51 -> -0.045408404
B45: Provisions | D45: 60509614 | E45: =-D45/D51 -> -0.023456755 | G45: 198061460 | H45: =-G45/G51 -> -0.10048124 | J45: 196291350 | K45: =-J45/J51 -> -0.10336082 | M45: 159546773 | N45: =-M45/M51 -> -0.088539626
D46: =SUM(D44:D45) -> 175759334 | G46: =SUM(G44:G45) -> 302721534 | J46: =SUM(J44:J45) -> 280189117 | M46: =SUM(M44:M45) -> 241371880
B48: Net Current Assets | D48: =D41-D46 -> 701909145 | E48: =D48/D51 -> 0.27209744 | F48: =F41-F46 -> 0 | G48: =G41-G46 -> 696420909 | H48: =G48/G51 -> 0.35331073 | I48: =I41-I46 -> 0 | J48: =J41-J46 -> 1367128629 | K48: =J48/J51 -> 0.71988674 | L48: =L41-L46 -> 0 | M48: =M41-M46 -> 1373179478 | N48: =M48/M51 -> 0.76203859
B49: 702209145 | C49: =B49-D48 -> 300000
B51: Total Assets | D51: =D31+D33+D48 -> 2579624248 | E51: =SUM(E27:E46) -> 1 | F51: =F31+F33+F48 -> 0 | G51: =G31+G33+G48 -> 1971128655 | H51: =SUM(H27:H46) -> 1 | I51: =I31+I33+I48 -> 0 | J51: =J31+J33+J48 -> 1899088506 | K51: =SUM(K27:K46) -> 1 | L51: =L31+L33+L48 -> 0 | M51: =M31+M33+M48 -> 1801981559 | N51: =SUM(N27:N46) -> 1

Sheet P&L
B5: Description | C5: Sch | D5: 31-Mar, 2009 | G5: 31-Mar, 2008 | J5: 31-Mar, 2007 | M5: 31-Mar, 2006
B7: Income
B8: Operating Income | D8: 943172538 | G8: 860233765 | J8: 811399400 | M8: 604170862
B9: Other Income | D9: 21900921 | G9: 61031746 | J9: 100451904 | M9: 20636020
B10: Total Income (Gross Income) | D10: =SUM(D8:D9) -> 965073459 | G10: =SUM(G8:G9) -> 921265511 | J10: =SUM(J8:J9) -> 911851304 | M10: =SUM(M8:M9) -> 624806882
B13: Expenditure
B14: Food and Beverages Consumed | D14: 84169657 | E14: =D14/D10 -> 0.087215803 | G14: 76164751 | H14: =G14/G10 -> 0.08267405 | J14: 64083974 | K14: =J14/J10 -> 0.070278974 | M14: 44236545 | N14: =M14/M10 -> 0.070800349
B15: Employee Costs | D15: 144122876 | E15: =D15/D10 -> 0.14933876 | G15: 97366817 | H15: =G15/G10 -> 0.10568812 | J15: 73292481 | K15: =J15/J10 -> 0.080377668 | M15: 55270026 | N15: =M15/M10 -> 0.088459375
B16: Other Operating Expenses | D16: 221255538 | E16: =D16/D10 -> 0.2292629 | G16: 149054101 | H16: =G16/G10 -> 0.16179277 | J16: 129002534 | K16: =J16/J10 -> 0.14147321 | M16: 102580284 | N16: =M16/M10 -> 0.16417918
B17: Selling, General and Adminstrative Expenses | D17: 191703941 | E17: =D17/D10 -> 0.19864181 | G17: 146070521 | H17: =G17/G10 -> 0.15855421 | J17: 140818691 | K17: =J17/J10 -> 0.15443164 | M17: 97398111 | N17: =M17/M10 -> 0.15588514
B18: Total Expense | D18: =SUM(D14:D17) -> 641252012 | G18: =SUM(G14:G17) -> 468656190 | J18: =SUM(J14:J17) -> 407197680 | M18: =SUM(M14:M17) -> 299484966
B21: Earnings Before Interest, Depreciation, Tax
B22: Gross Profit (EBITDA) with YOY change | D22: =D10-D18 -> 323821447 | E22: =(D22-G22)/G22 -> -0.28454534 | F22: =F10-F18 -> 0 | G22: =G10-G18 -> 452609321 | H22: =(G22-J22)/J22 -> -0.10312876 | J22: =J10-J18 -> 504653624 | K22: =(J22-M22)/M22 -> 0.55124386 | L22: =L10-L18 -> 0 | M22: =M10-M18 -> 325321916
B25: Earnings Before Interest, Tax
B26: Depreciation/Amortization | D26: 56988124 | E26: =D26/D10 -> 0.059050556 | G26: 32147661 | H26: =G26/G10 -> 0.03489511 | J26: 33333547 | K26: =J26/J10 -> 0.036555902 | M26: 26050364 | N26: =M26/M10 -> 0.041693465
B27: Earnings Before Interest, Tax (EBIT) | D27: =D22-D26 -> 266833323 | F27: =F22-F26 -> 0 | G27: =G22-G26 -> 420461660 | J27: =J22-J26 -> 471320077 | L27: =L22-L26 -> 0 | M27: =M22-M26 -> 299271552
B30: Earnings Before Tax
B31: Interest | D31: 16480773 | E31: =D31/D10 -> 0.017077221 | G31: 20913352 | H31: =G31/G10 -> 0.022700678 | J31: 21557837 | K31: =J31/J10 -> 0.023641834 | M31: 15753431 | N31: =M31/M10 -> 0.02521328
B32: Profit Before Tax - PBT | D32: =D27-D31 -> 250352550 | F32: =F26-F31 -> 0 | G32: =G27-G31 -> 399548308 | J32: =J27-J31 -> 449762240 | L32: =L26-L31 -> 0 | M32: =M27-M31 -> 283518121
B35: PBT with and without Prior Period Items
B36: Profit Before Tax and Prior Period Items | D36: =D32 -> 250352550 | F36: =F27 -> 0 | G36: =G32 -> 399548308 | J36: =J32 -> 449762240 | L36: =L27 -> 0 | M36: =M32 -> 283518121
B37: Prior Period Income | D37: 11137847 | G37: 0 | J37: 0 | M37: 0
B38: Profit After Tax and Prior Period Items | D38: =D36+D37 -> 261490397 | F38: =F36+F37 -> 0 | G38: =G36+G37 -> 399548308 | J38: =J36+J37 -> 449762240 | L38: =L36+L37 -> 0 | M38: =M36+M37 -> 283518121
B41: Provision for Income Tax
B42: Current Tax | D42: -50000000 | G42: -83000000 | J42: -111500000 | M42: -61000000
B43: Fringe Benefit Tax | D43: -1800000 | G43: -1797199 | J43: -1397055 | M43: -1374318
B44: Prior Years Taxes | D44: -2784462 | G44: -951304 | J44: 0 | M44: 200000
B45: Deferred Tax charge | D45: -14000000 | G45: -7000000 | J45: 2200000 | M45: -9300000
D46: =SUM(D42:D45) -> -68584462 | G46: =SUM(G42:G45) -> -92748503 | J46: =SUM(J42:J45) -> -110697055 | M46: =SUM(M42:M45) -> -71474318
B49: Profit After Tax - PAT | D49: =D38+D46 -> 192905935 | E49: =D49/D10 -> 0.19988731 | F49: =F38+F46 -> 0 | G49: =G38+G46 -> 306799805 | H49: =G49/G10 -> 0.33301996 | J49: =J38+J46 -> 339065185 | K49: =J49/J10 -> 0.37184263 | L49: =L38+L46 -> 0 | M49: =M38+M46 -> 212043803 | N49: =M49/M10 -> 0.33937495
B50: PAT - YOY change | E50: =(D49-G49)/G49 -> -0.37123189 | H50: =(G49-J49)/J49 -> -0.095159814 | K50: =(J49-M49)/M49 -> 0.59903369
B53: Balance brought forward from Prev year | D53: =G65 -> 270973702 | E53: =H65 -> 0.70486259 | F53: =I65 -> 0 | G53: =J65 -> 186048161 | H53: =K65 -> 0.37184263 | I53: =L65 -> 0 | J53: =M65 -> 72101442 | L53: =L47-L59 -> 0 | M53: 133729362
B54: Ammount available for Appropriations | D54: =D49+D53 -> 463879637 | E54: =E49+E53 -> 0.9047499 | F54: =F49+F53 -> 0 | G54: =G49+G53 -> 492847966 | H54: =H49+H53 -> 0.70486259 | I54: =I49+I53 -> 0 | J54: =J49+J53 -> 411166627 | K54: =K49+K53 -> 0.37184263 | ... N54: =N49+N53 -> 0.33937495
B57: Appropriations
B58: Proposed Dividend | D58: -40850948 | G58: -163403790 | J58: -163403790 | M58: -136169825
B59: Dividend Tax | D59: -6942619 | G59: -27770474 | J59: -27770474 | M59: -19097818
B60: Transfer to General Reserve | D60: -9645297 | G60: -30700000 | J60: -33944202 | M60: -21204380
B61: Bonus Shares issued | M61: -97199700
D62: =SUM(D58:D60) -> -57438864 | G62: =SUM(G58:G60) -> -221874264 | J62: =SUM(J58:J60) -> -225118466 | M62: =SUM(M58:M61) -> -273671723
B65: Profit or Loss Carried to Balance Sheet | D65: =D54+D62 -> 406440773 | E65: =E54+E62 -> 0.9047499 | F65: =F54+F62 -> 0 | G65: =G54+G62 -> 270973702 | H65: =H54+H62 -> 0.70486259 | I65: =I54+I62 -> 0 | J65: =J54+J62 -> 186048161 | K65: =K54+K62 -> 0.37184263 | ... N65: =N54+N62 -> 0.33937495
...

Sheet Comparison Ratio
B3: Ratio | C3: Ideal Value | D3: 31-Mar, 2009 | G3: 31-Mar, 2008 | J3: 31-Mar, 2007 | M3: 31-Mar, 2006 | P3: Remark
B5: Liquidity Ratios
B6: Current Ratio | C6: 2 | D6: =(BalanceSheet!D41)/(BalanceSheet!D46) -> 4.993581 | G6: =(BalanceSheet!G41)/(BalanceSheet!G46) -> 3.3005331 | J6: =(BalanceSheet!J41)/(BalanceSheet!J46) -> 5.8793067 | M6: =(BalanceSheet!M41)/(BalanceSheet!M46) -> 6.6890615
B7: Acid Test (Quick Ratio) | C7: 1 | D7: =( (BalanceSheet!D37)+(BalanceSheet!D39) )/(BalanceSheet!D46) -> 1.6374857 | G7: =( (BalanceSheet!G37)+(BalanceSheet!G39) )/(BalanceSheet!G46) -> 1.6554849 | J7: =( (BalanceSheet!J37)+(BalanceSheet!J39) )/(BalanceSheet!J46) -> 4.4774455 | M7: =( (BalanceSheet!M37)+(BalanceSheet!M39) )/(BalanceSheet!M46) -> 5.9483147 | P7: Will Unbilled revenue be added here - ?
B8: Avg Per day Sales - 360 days in million | D8: =('P&L'!D8)/(360 * 1000000) -> 2.6199237 | G8: =('P&L'!G8)/(360 * 1000000) -> 2.3895382 | J8: =('P&L'!J8)/(360 * 1000000) -> 2.2538872 | M8: =('P&L'!M8)/(360 * 1000000) -> 1.6782524
B9: Avg Collection Period (Debtors Collection Period) in days | D9: =(BalanceSheet!D37)/(D8 * 1000000) -> 23.147262 | G9: =(BalanceSheet!G37)/(G8 * 1000000) -> 13.902408 | J9: =(BalanceSheet!J37)/(J8 * 1000000) -> 19.636959 | M9: =(BalanceSheet!M37)/(M8 * 1000000) -> 20.39161
B10: Cost of Goods Sales per Day - 360 days in million | D10: =('P&L'!D18)/(360 * 1000000) -> 1.7812556 | G10: =('P&L'!G18)/(360 * 1000000) -> 1.3018227 | J10: =('P&L'!J18)/(360 * 1000000) -> 1.1311047 | M10: =('P&L'!M18)/(360 * 1000000) -> 0.83190268 | P10: Whether Depreciation needs to be added here - ?
B11: Avg Inventory Holding Period (Stock Velocity) in days | D11: =(BalanceSheet!D36)/(D8 * 1000000) -> 4.0970399 | G11: =(BalanceSheet!G36)/(G8 * 1000000) -> 4.8771816 | J11: =(BalanceSheet!J36)/(J8 * 1000000) -> 2.2359065 | M11: =(BalanceSheet!M36)/(M8 * 1000000) -> 3.2105809
B15: Leverage Ratio
B16: Financial Leverage Ratio
B17: Debt to Equity Ratio | C17: 2 | D17: =(BalanceSheet!D18)/(BalanceSheet!D13) -> 0.32452349 | G17: =(BalanceSheet!G18)/(BalanceSheet!G13) -> 0.096269887 | J17: =(BalanceSheet!J18)/(BalanceSheet!J13) -> 0.13417934 | M17: =(BalanceSheet!M18)/(BalanceSheet!M13) -> 0.17987623
B18: Debt to Capitalization Ratio | D18: =(BalanceSheet!D18)/((BalanceSheet!D18) + (BalanceSheet!D13) ) -> 0.2450115 | G18: =(BalanceSheet!G18)/((BalanceSheet!G18) + (BalanceSheet!G13) ) -> 0.087815863 | J18: =(BalanceSheet!J18)/((BalanceSheet!J18) + (BalanceSheet!J13) ) -> 0.11830522 | M18: =(BalanceSheet!M18)/((BalanceSheet!M18) + (BalanceSheet!M13) ) -> 0.15245348
B19: Times Interest Earned | D19: =('P&L'!D27)/('P&L'!D31) -> 16.190583 | G19: =('P&L'!G27)/('P&L'!G31) -> 20.104939 | J19: =('P&L'!J27)/('P&L'!J31) -> 21.86305 | M19: =('P&L'!M27)/('P&L'!M31) -> 18.99723
B23: Profitability Ratio
B24: Gross Margin | D24: =('P&L'!D22)/('P&L'!D8) -> 0.34333214 | G24: =('P&L'!G22)/('P&L'!G8) -> 0.52614689 | J24: =('P&L'!J22)/('P&L'!J8) -> 0.62195464 | M24: =('P&L'!M22)/('P&L'!M8) -> 0.53846012 | P24: For profit margin calculation, whether other source of income will be considered
B25: Net Profit | D25: =('P&L'!D49)/('P&L'!D8) -> 0.20452879 | G25: =('P&L'!G49)/('P&L'!G8) -> 0.35664702 | J25: =('P&L'!J49)/('P&L'!J8) -> 0.41787705 | M25: =('P&L'!M49)/('P&L'!M8) -> 0.35096662 | P25: same as above
B26: Return on Investment (ROI) | D26: =('P&L'!D27)/( (BalanceSheet!D13) + (BalanceSheet!D18) ) -> 0.1056379 | G26: =('P&L'!G27)/( (BalanceSheet!G13) + (BalanceSheet!G18) ) -> 0.21772846 | J26: =('P&L'!J27)/( (BalanceSheet!J13) + (BalanceSheet!J18) ) -> 0.25257113 | M26: =('P&L'!M27)/( (BalanceSheet!M13) + (BalanceSheet!M18) ) -> 0.16938798 | P26: Do we need to consider DTL for calculating Shareholder funds
B27: Return on Equity (ROE) | D27: =('P&L'!D27)/( (BalanceSheet!D13) ) -> 0.13991987 | G27: =('P&L'!G27)/( (BalanceSheet!G13) ) -> 0.23868915 | J27: =('P&L'!J27)/( (BalanceSheet!J13) ) -> 0.28646095 | M27: =('P&L'!M27)/( (BalanceSheet!M13) ) -> 0.19985685
B31: Turnover Ratio
B32: Fixed Asset Turnover | D32: =('P&L'!D8)/(BalanceSheet!D29) -> 1.6392878 | G32: =('P&L'!G8)/(BalanceSheet!G29) -> 1.5940775 | J32: =('P&L'!J8)/(BalanceSheet!J29) -> 1.9280437 | M32: =('P&L'!M8)/(BalanceSheet!M29) -> 1.6859822 | P32: Will other source of income will be considered - ?
B33: Current Asset Turnover | D33: =('P&L'!D8)/(BalanceSheet!D41) -> 1.0746342 | G33: =('P&L'!G8)/(BalanceSheet!G41) -> 0.8609721 | J33: =('P&L'!J8)/(BalanceSheet!J41) -> 0.49255792 | M33: =('P&L'!M8)/(BalanceSheet!M41) -> 0.37420356
B34: Inventory Turnover | D34: =('P&L'!D8)/(BalanceSheet!D36) -> 87.868317 | G34: =('P&L'!G8)/(BalanceSheet!G36) -> 73.813121 | J34: =('P&L'!J8)/(BalanceSheet!J36) -> 161.00852 | M34: =('P&L'!M8)/(BalanceSheet!M36) -> 112.12924 | P34: Whether Net Sales or COGS required to use for Inventory Turnover
B35: Total Asset Turnover | D35: =('P&L'!D8)/(BalanceSheet!D51) -> 0.365624 | G35: =('P&L'!G8)/(BalanceSheet!G51) -> 0.43641685 | J35: =('P&L'!J8)/(BalanceSheet!J51) -> 0.42725729 | M35: =('P&L'!M8)/(BalanceSheet!M51) -> 0.33528138 | P35: Here Entire Asset is added or just FA and CA - Investment
B36: Cash Turnover Ratio - Cash Velocity | D36: =('P&L'!D8)/( (BalanceSheet!D37) + (BalanceSheet!D39) ) -> 3.2771418 | G36: =('P&L'!G8)/( (BalanceSheet!G37) + (BalanceSheet!G39) ) -> 1.7165163 | J36: =('P&L'!J8)/( (BalanceSheet!J37) + (BalanceSheet!J39) ) -> 0.64677483 | M36: =('P&L'!M8)/( (BalanceSheet!M37) + (BalanceSheet!M39) ) -> 0.42080333
B41: Market Indicators
B42: EPS - Basic | D42: ='P&L'!D68 -> 0 | E42: ='P&L'!E68 -> 0 | F42: ='P&L'!F68 -> 0 | G42: ='P&L'!G68 -> 0 | H42: ='P&L'!H68 -> 0 | J42: ='P&L'!J68 -> 0 | K42: ='P&L'!K68 -> 0 | L42: ='P&L'!L68 -> 0 | M42: ='P&L'!M68 -> 0 | N42: ='P&L'!N68 -> 0 | O42: ='P&L'!O68 -> 0
B43: EPS - Dilute | D43: ='P&L'!D71 -> 7.083285 | E43: ='P&L'!E71 -> 0 | G43: ='P&L'!G71 -> 11.265337 | H43: ='P&L'!H71 -> 0 | J43: ='P&L'!J71 -> 12.450085 | K43: ='P&L'!K71 -> 0 | M43: ='P&L'!M71 -> 7.7860056 | N43: ='P&L'!N71 -> 0
B44: Price Earning Ratio, Assume current Share price as Rs85 | D44: =85/D43 -> 12.000082 | G44: =85/G43 -> 7.5452689 | J44: =85/J43 -> 6.8272625 | M44: =85/M43 -> 10.917023
B45: Book Value | D45: =( (BalanceSheet!D13) + (BalanceSheet!D18) )/(BalanceSheet!D13) -> 1.3245235 | J45: =( (BalanceSheet!J13) + (BalanceSheet!J18) )/(BalanceSheet!J13) -> 1.1341793 | P45: How its calculated
B46: Market to Book value, Assume current Share price as Rs85 | D46: =C44/D45 -> 0 | P46: same as above
B47: Dividend Yield | D47: =1.5/85 -> 0.017647059 | G47: =6/119 -> 0.050420168 | P47: Calculated with current Mkt and closing date price
B48: Yield | D48: =(5+1.5)/85 -> 0.076470588 | G48: =25/119 -> 0.21008403

Sheet Conclusion
B3: Conclusion
B4: S.no | C4: Observation | D4: Indicator/Remark
B5: 1 | C5: Usually, Hotel Industry goes in tandem with economy boom and dull phase. And its affect is clearly visible in companies performance.
B6: 2 | C6: Severe affect of slowdown can be observed in hotel industry. Sharp decline in Earnings, EBIT, PAT. | D6: Down
B7: 3 | C7: However, Company is using slow down for expansion in Hyderabad with debt money of Rs30Cr.
B8: 4 | C8: Huge cash reserve in bank, which is not judicially used | D8: Not Properly Managed
B9: 5 | C9: No Transaction were done in investment. Investment could have been used as hedging during slowdown for improving the margin | D9: Not Properly Managed
B10: 6 | C10: Due to interest, PBT will be under pressure. If sales are improved due to expansion, PBT may improve | D10: Based on demand pick-up
B11: 7 | C11: Higher dividend is declared in Yr 2008. Company could have added more retained earnings so that Loan component could have been reduced | D11: -
B12: 8 | C12: For All loans, promoter has given personal guaranty
B13: 9 | C13: Short term corporate loan is utilized for Hotel construction, which can be renewed after one yr | D13: Strange
B14: 10 | C14: 1project expected to complete in Dec, 2009 and another 2 Projects are expected to complete by end of 2010. So there is fair possibility of margin improving in future. | D14: Outlooks looks good provided demand picksup
C17: Questions/Clarifications
B19: 1 | C19: How Balance sheet can have Typo mistake-? Yr 2009 has some minor error with respect to Rs 3L
B20: 2 | C20: For ROI, Do we need to consider DTL - ?
B21: 3 | C21: Will unbilled revenue be added to calculate Quick ratio - ?
B22: 4 | C22: For COGS, whether depreciation will be taken into account - ?
B23: 5 | C23: For Gross Profit Margin, whether other source of income is considered - ?
B24: 6 | C24: Asset Turnover, whether Total Assets includes investments as well - ?
B25: 7 | C25: calulation of Book value - ?

Sheet Draft
B3: Observation:
B4: 1 | C4: EPS came down
B5: 2 | C5: Debt component (in 2009) increased for expansion purpose.
B6: 3 | C6: No transactions occurred in investments
B7: 4 | C7: For all loans, Owner has given personal gurantee
B8: 5 | C8: Although Gross profit increased but due to higher depreciation net profit margin came down.
B9: 6 | C9: Short term corporate loan is utilized for house construction.
B10: 7 | C10: From next year onwards, Interest will be added for new short term loan which would further reduce the net profit margin.
B11: 8 | C11: Other income is improving the margin
B17: 1 | C17: Independent Director - Mr Jaithirth Rao not attending all AGM meeting - What to Infer?
B18: 2
B19: 3 | C19: Management And technical fee is recognized as Income
